Workbook

Sheet All sensors Installed
A1: 78d800b023960383 | G1: 1 | H1: 2 | I1: 3 | K1: LoRaWAN and test codes | U1: All Other connection Reference
A2: ID | B2: PILOT REF | C2: Name | D2: Lon | E2: Lat | F2: Device Type | G2: FUNCTION | H2: BRAND | I2: MODEL | K2: DEVICE EUI | L2: APP EUI (SN for Gateway) | M2: APP KEY | N2: Device Address | O2: AppSKey | P2: NwkSKey | Q2: TB token | R2: Communication check | S2: Decoding check | U2: EndPoint | V2: EndPoint Type | W2: UserName | X2: Password | Y2: Device ID | Z2: Communication check | AA2: Decoding check | AB2: MEASUREMENTS | AC2: Notes | AD2: @dropdown
A3: DGW01 | B3: Demo | C3: RAK | D3: 8.564322 | E3: 40.726754 | F3: GT1 | G3: =HLOOKUP($F3,'Sensor Type Details'!$B$1:$R$4,G$1+1) -> Gateway | H3: =HLOOKUP($F3,'Sensor Type Details'!$B$1:$R$4,H$1+1) -> Rackwireless | I3: =HLOOKUP($F3,'Sensor Type Details'!$B$1:$R$4,I$1+1) -> RAK7240 | J3: =K1 -> LoRaWAN and test codes | K3: AC1F09FFFE091FBA | L3: 9181000G6020915013 | T3: =U1 -> All Other connection Reference
A4: D001 | B4: Demo | C4: SenseCAPS2103 | D4: 8.564322 | E4: 40.726754 | F4: ST01 | G4: =HLOOKUP($F4,'Sensor Type Details'!$B$1:$R$4,G$1+1) -> Sensor | H4: =HLOOKUP($F4,'Sensor Type Details'!$B$1:$R$4,H$1+1) -> Seeeds | I4: =HLOOKUP($F4,'Sensor Type Details'!$B$1:$R$4,I$1+1) -> SenseCAPS2103 | K4: 2cf7f1c043500183 | L4: 2E3F1EFBCD63BC37 | M4: 9FB06416DFFCCE752077C9BC030FDF50 | Q4: isvHssKmSlqaKqlOF2E0 | R4: ok | S4: ok | AB4: Air temperature, Air humidity, CO2 concentration
A5: D002 | B5: Demo | C5: SenseCAPS868 | D5: 8.564322 | E5: 40.726754 | F5: ST02 | G5: =HLOOKUP($F5,'Sensor Type Details'!$B$1:$R$4,G$1+1) -> Sensor | H5: =HLOOKUP($F5,'Sensor Type Details'!$B$1:$R$4,H$1+1) -> Seeeds | I5: =HLOOKUP($F5,'Sensor Type Details'!$B$1:$R$4,I$1+1) -> SenseCAP Soil Moisture and Temperature | K5: 2CF7F12031500017 | L5: 8000000000000009 | M5: DE914F209AC8A89E4BBB494EDA525441 | Q5: lsp4QbMlO7zaYLzZ2BA1 | R5: ok | S5: ok | AB5: Soil moisture & Temperature
A6: D003 | B6: Demo | C6: LoRa_Controller-UC511 | D6: 8.564322 | E6: 40.726754 | F6: ST03 | G6: =HLOOKUP($F6,'Sensor Type Details'!$B$1:$R$4,G$1+1) -> Sensor | H6: =HLOOKUP($F6,'Sensor Type Details'!$B$1:$R$4,H$1+1) -> Milesight | I6: =HLOOKUP($F6,'Sensor Type Details'!$B$1:$R$4,I$1+1) -> LoRa_Controlle-UC511 | K6: 24e124414b106165 | L6: 24E124C0002A0001 | M6: 5572404C696E6B4C6F52613230313823 | Q6: ORwcidwrRPfXNq3n6NJZ | R6: ok | S6: ok | AB6: 2 x Valve state & Controll
A7: D004 | B7: Demo | C7: SenProbe-3A | D7: 8.564322 | E7: 40.726754 | F7: ST04 | G7: =HLOOKUP($F7,'Sensor Type Details'!$B$1:$R$4,G$1+1) -> Sensor | H7: =HLOOKUP($F7,'Sensor Type Details'!$B$1:$R$4,H$1+1) -> IQNexus | I7: =HLOOKUP($F7,'Sensor Type Details'!$B$1:$R$4,I$1+1) -> SenProbe - 3B-LR12 | K7: AC1F09FFFE04E43F | L7: 0101010101010101 | M7: 2B7E151628AED2A6ABF7158809CF4F3C | Q7: NXUY6jsih4vggsxt2APd | R7: ok | S7: ok | AB7: 6X Soil moisture & Soil Temperature + Air Temperature
A8: D005 | B8: Demo | C8: SenPulse-3V | D8: 8.564322 | E8: 40.726754 | F8: ST05 | G8: =HLOOKUP($F8,'Sensor Type Details'!$B$1:$R$4,G$1+1) -> Sensor | H8: =HLOOKUP($F8,'Sensor Type Details'!$B$1:$R$4,H$1+1) -> IQNexus | I8: =HLOOKUP($F8,'Sensor Type Details'!$B$1:$R$4,I$1+1) -> SenPulse-PCT-3A-LR-S | K8: 3738383962376102 | L8: D34B2F28A10C8DB0 | M8: D927A47631ECF07A09A2132A66212379 | Q8: YHYEONmduF3tDNFyBttK | R8: ok | S8: ok | AB8: Pulse Totaliser
L9: 101010101010101
A10: PILOT - ITALY
A11: IGW01 | B11: ITALY | C11: RAK-UNISS-2 | D11: 8.6995 | E11: 39.9437 | F11: GT1 | G11: =HLOOKUP($F11,'Sensor Type Details'!$B$1:$R$4,G$1+1) -> Gateway | H11: =HLOOKUP($F11,'Sensor Type Details'!$B$1:$R$4,H$1+1) -> Rackwireless | I11: =HLOOKUP($F11,'Sensor Type Details'!$B$1:$R$4,I$1+1) -> RAK7240 | K11: AC1f09FFFE1042C3 | L11: 918100QN6040424007
A12: IGW02 | B12: ITALY | C12: RAK-UNISS-1 | D12: 8.5535 | E12: 39.7788 | F12: GT1 | G12: =HLOOKUP($F12,'Sensor Type Details'!$B$1:$R$4,G$1+1) -> Gateway | H12: =HLOOKUP($F12,'Sensor Type Details'!$B$1:$R$4,H$1+1) -> Rackwireless | I12: =HLOOKUP($F12,'Sensor Type Details'!$B$1:$R$4,I$1+1) -> RAK7240 | K12: AC1F09FFFE0BB7A9 | L12: 918100QN6030313015
A13: I001 | B13: ITALY | C13: SoilMoisture1 | D13: 8.54903 | E13: 39.77597 | F13: ST04 | G13: =HLOOKUP($F13,'Sensor Type Details'!$B$1:$R$4,G$1+1) -> Sensor | H13: =HLOOKUP($F13,'Sensor Type Details'!$B$1:$R$4,H$1+1) -> IQNexus | I13: =HLOOKUP($F13,'Sensor Type Details'!$B$1:$R$4,I$1+1) -> SenProbe - 3B-LR12 | K13: AC1F09FFFE04E48A | L13: 0101010101010101 | M13: 2B7E151628AED2A6ABF7158809CF4F3C | R13: ok | AB13: 6X Soil moisture & Soil Temperature + Air Temperature
A14: I002 | B14: ITALY | C14: SoilMoisture2 | D14: 8.5485 | E14: 39.77614 | F14: ST04 | G14: =HLOOKUP($F14,'Sensor Type Details'!$B$1:$R$4,G$1+1) -> Sensor | H14: =HLOOKUP($F14,'Sensor Type Details'!$B$1:$R$4,H$1+1) -> IQNexus | I14: =HLOOKUP($F14,'Sensor Type Details'!$B$1:$R$4,I$1+1) -> SenProbe - 3B-LR12 | K14: AC1F09FFFE04E487 | L14: 0101010101010101 | M14: 2B7E151628AED2A6ABF7158809CF4F3C | R14: ok | AB14: 6X Soil moisture & Soil Temperature + Air Temperature
A15: I003 | B15: ITALY | C15: SoilMoisture3 | D15: 8.580694 | E15: 39.76103 | F15: ST04 | G15: =HLOOKUP($F15,'Sensor Type Details'!$B$1:$R$4,G$1+1) -> Sensor | H15: =HLOOKUP($F15,'Sensor Type Details'!$B$1:$R$4,H$1+1) -> IQNexus | I15: =HLOOKUP($F15,'Sensor Type Details'!$B$1:$R$4,I$1+1) -> SenProbe - 3B-LR12 | K15: AC1F09FFFE04E4C1 | L15: 0101010101010101 | M15: 2B7E151628AED2A6ABF7158809CF4F3C | R15: ok | AB15: 6X Soil moisture & Soil Temperature + Air Temperature
A16: I004 | B16: ITALY | C16: SoilMoisture4 | D16: 8.5815 | E16: 39.76139 | F16: ST04 | G16: =HLOOKUP($F16,'Sensor Type Details'!$B$1:$R$4,G$1+1) -> Sensor | H16: =HLOOKUP($F16,'Sensor Type Details'!$B$1:$R$4,H$1+1) -> IQNexus | I16: =HLOOKUP($F16,'Sensor Type Details'!$B$1:$R$4,I$1+1) -> SenProbe - 3B-LR12 | K16: AC1F09FFFE04E4B1 | L16: 0101010101010101 | M16: 2B7E151628AED2A6ABF7158809CF4F3C | R16: ok | AB16: 6X Soil moisture & Soil Temperature + Air Temperature
A17: I005 | B17: ITALY | C17: SoilMoisture5 | D17: 8.69725 | E17: 39.94489 | F17: ST04 | G17: =HLOOKUP($F17,'Sensor Type Details'!$B$1:$R$4,G$1+1) -> Sensor | H17: =HLOOKUP($F17,'Sensor Type Details'!$B$1:$R$4,H$1+1) -> IQNexus | I17: =HLOOKUP($F17,'Sensor Type Details'!$B$1:$R$4,I$1+1) -> SenProbe - 3B-LR12 | K17: AC1F09FFFE04DB8D | L17: 0101010101010101 | M17: 2B7E151628AED2A6ABF7158809CF4F3C | R17: ok | AB17: 6X Soil moisture & Soil Temperature + Air Temperature
A18: I006 | B18: ITALY | C18: SoilMoisture6 | D18: 8.703639 | E18: 39.94833 | F18: ST04 | G18: =HLOOKUP($F18,'Sensor Type Details'!$B$1:$R$4,G$1+1) -> Sensor | H18: =HLOOKUP($F18,'Sensor Type Details'!$B$1:$R$4,H$1+1) -> IQNexus | I18: =HLOOKUP($F18,'Sensor Type Details'!$B$1:$R$4,I$1+1) -> SenProbe - 3B-LR12 | K18: AC1F09FFFE04E488 | L18: 0101010101010101 | M18: 2B7E151628AED2A6ABF7158809CF4F3C | R18: ok | AB18: 6X Soil moisture & Soil Temperature + Air Temperature
A19: I007 | B19: ITALY | C19: SoilMoisture7 | D19: 8.68192 | E19: 39.94853 | F19: ST04 | G19: =HLOOKUP($F19,'Sensor Type Details'!$B$1:$R$4,G$1+1) -> Sensor | H19: =HLOOKUP($F19,'Sensor Type Details'!$B$1:$R$4,H$1+1) -> IQNexus | I19: =HLOOKUP($F19,'Sensor Type Details'!$B$1:$R$4,I$1+1) -> SenProbe - 3B-LR12 | K19: AC1F09FFFE04E284 | L19: 0101010101010101 | M19: 2B7E151628AED2A6ABF7158809CF4F3C | R19: ok | AB19: 6X Soil moisture & Soil Temperature + Air Temperature
A20: I008 | B20: ITALY | C20: SoilMoisture8 | D20: 8.680194 | E20: 39.94869 | F20: ST04 | G20: =HLOOKUP($F20,'Sensor Type Details'!$B$1:$R$4,G$1+1) -> Sensor | H20: =HLOOKUP($F20,'Sensor Type Details'!$B$1:$R$4,H$1+1) -> IQNexus | I20: =HLOOKUP($F20,'Sensor Type Details'!$B$1:$R$4,I$1+1) -> SenProbe - 3B-LR12 | K20: AC1F09FFFE04E2CB | L20: 0101010101010101 | M20: 2B7E151628AED2A6ABF7158809CF4F3C | R20: ok | AB20: 6X Soil moisture & Soil Temperature + Air Temperature
A21: I009 | B21: ITALY | C21: SoilMoisture9 | D21: 8.53533 | E21: 39.71772 | F21: ST04 | G21: =HLOOKUP($F21,'Sensor Type Details'!$B$1:$R$4,G$1+1) -> Sensor | H21: =HLOOKUP($F21,'Sensor Type Details'!$B$1:$R$4,H$1+1) -> IQNexus | I21: =HLOOKUP($F21,'Sensor Type Details'!$B$1:$R$4,I$1+1) -> SenProbe - 3B-LR12 | K21: AC1F09FFFE04E240 | L21: 0101010101010101 | M21: 2B7E151628AED2A6ABF7158809CF4F3C | AB21: 6X Soil moisture & Soil Temperature + Air Temperature
A22: I010 | B22: ITALY | C22: SoilMoisture10 | D22: 8.53531 | E22: 39.71847 | F22: ST04 | G22: =HLOOKUP($F22,'Sensor Type Details'!$B$1:$R$4,G$1+1) -> Sensor | H22: =HLOOKUP($F22,'Sensor Type Details'!$B$1:$R$4,H$1+1) -> IQNexus | I22: =HLOOKUP($F22,'Sensor Type Details'!$B$1:$R$4,I$1+1) -> SenProbe - 3B-LR12 | K22: AC1F09FFFE04E312 | L22: 0101010101010101 | M22: 2B7E151628AED2A6ABF7158809CF4F3C | AB22: 6X Soil moisture & Soil Temperature + Air Temperature
A23: I011 | B23: ITALY | C23: WaterMeter1 | D23: 8.69725 | E23: 39.94489 | F23: ST06 | G23: =HLOOKUP($F23,'Sensor Type Details'!$B$1:$R$4,G$1+1) -> Sensor | H23: =HLOOKUP($F23,'Sensor Type Details'!$B$1:$R$4,H$1+1) -> Maddalena | I23: =HLOOKUP($F23,'Sensor Type Details'!$B$1:$R$4,I$1+1) -> Arrow split 2 | K23: 78D800B023960378 | L23: 0101010101010101 | M23: DAE982C90EE7BDA3CB86210F349A4D8C | R23: ok | S23: ok | AB23: Water flow
A24: I012 | B24: ITALY | C24: WaterMeter2 | F24: ST06 | G24: =HLOOKUP($F24,'Sensor Type Details'!$B$1:$R$4,G$1+1) -> Sensor | H24: =HLOOKUP($F24,'Sensor Type Details'!$B$1:$R$4,H$1+1) -> Maddalena | I24: =HLOOKUP($F24,'Sensor Type Details'!$B$1:$R$4,I$1+1) -> Arrow split 2 | K24: 78D800B023960379 | L24: 0101010101010101 | M24: AF08096331115DE4E72269A3FF27C6FE | S24: ok | AB24: Water flow
A25: I013 | B25: ITALY | C25: WaterMeter3 | D25: 8.680194 | E25: 39.94869 | F25: ST06 | G25: =HLOOKUP($F25,'Sensor Type Details'!$B$1:$R$4,G$1+1) -> Sensor | H25: =HLOOKUP($F25,'Sensor Type Details'!$B$1:$R$4,H$1+1) -> Maddalena | I25: =HLOOKUP($F25,'Sensor Type Details'!$B$1:$R$4,I$1+1) -> Arrow split 2 | K25: 78D800B023960380 | L25: 0101010101010101 | M25: 31EA10B723E4BB3C4C54E29863CA219F | S25: ok | AB25: Water flow
A26: I014 | B26: ITALY | C26: WaterMeter4 | D26: 8.68192 | E26: 39.94853 | F26: ST06 | G26: =HLOOKUP($F26,'Sensor Type Details'!$B$1:$R$4,G$1+1) -> Sensor | H26: =HLOOKUP($F26,'Sensor Type Details'!$B$1:$R$4,H$1+1) -> Maddalena | I26: =HLOOKUP($F26,'Sensor Type Details'!$B$1:$R$4,I$1+1) -> Arrow split 2 | K26: 78D800B023960381 | L26: 0101010101010101 | M26: 722D42E0C4946986E1B0386AE648AC5E | S26: ok | AB26: Water flow
A27: I015 | B27: ITALY | C27: WaterMeter5 | D27: 8.54903 | E27: 39.77597 | F27: ST06 | G27: =HLOOKUP($F27,'Sensor Type Details'!$B$1:$R$4,G$1+1) -> Sensor | H27: =HLOOKUP($F27,'Sensor Type Details'!$B$1:$R$4,H$1+1) -> Maddalena | I27: =HLOOKUP($F27,'Sensor Type Details'!$B$1:$R$4,I$1+1) -> Arrow split 2 | K27: 78D800B023960382 | L27: 0101010101010101 | M27: 294F8ED6861B691D3CD623E0FB9B79C5 | S27: ok | AB27: Water flow
A28: I016 | B28: ITALY | C28: WaterMeter6 | D28: 8.5485 | E28: 39.77614 | F28: ST06 | G28: =HLOOKUP($F28,'Sensor Type Details'!$B$1:$R$4,G$1+1) -> Sensor | H28: =HLOOKUP($F28,'Sensor Type Details'!$B$1:$R$4,H$1+1) -> Maddalena | I28: =HLOOKUP($F28,'Sensor Type Details'!$B$1:$R$4,I$1+1) -> Arrow split 2 | K28: 78D800B023960383 | L28: 0101010101010101 | M28: 5F7A39E4C8EB51602ACA7BB0EAF6B293 | S28: ok | AB28: Water flow
A29: I017 | B29: ITALY | C29: WaterMeter7 | D29: 8.580694 | E29: 39.76103 | F29: ST06 | G29: =HLOOKUP($F29,'Sensor Type Details'!$B$1:$R$4,G$1+1) -> Sensor | H29: =HLOOKUP($F29,'Sensor Type Details'!$B$1:$R$4,H$1+1) -> Maddalena | I29: =HLOOKUP($F29,'Sensor Type Details'!$B$1:$R$4,I$1+1) -> Arrow split 2 | K29: 78D800B023960384 | L29: 0101010101010101 | M29: E0DF3488DCA1A263DF84795017910EDD | S29: ok | AB29: Water flow
A30: I018 | B30: ITALY | C30: WaterMeter8 | D30: 8.5815 | E30: 39.76139 | F30: ST06 | G30: =HLOOKUP($F30,'Sensor Type Details'!$B$1:$R$4,G$1+1) -> Sensor | H30: =HLOOKUP($F30,'Sensor Type Details'!$B$1:$R$4,H$1+1) -> Maddalena | I30: =HLOOKUP($F30,'Sensor Type Details'!$B$1:$R$4,I$1+1) -> Arrow split 2 | K30: 78D800B023960385 | L30: 0101010101010101 | M30: 441F38EFADDE87AFE973207044BAC61E | S30: ok | AB30: Water flow
A31: I019 | B31: ITALY | C31: WaterMeter9 | D31: 8.53533 | E31: 39.71772 | F31: ST06 | G31: =HLOOKUP($F31,'Sensor Type Details'!$B$1:$R$4,G$1+1) -> Sensor | H31: =HLOOKUP($F31,'Sensor Type Details'!$B$1:$R$4,H$1+1) -> Maddalena | I31: =HLOOKUP($F31,'Sensor Type Details'!$B$1:$R$4,I$1+1) -> Arrow split 2 | K31: 78D800B023960386 | L31: 0101010101010101 | M31: C38B6B249BF2E1F8C70A7EFAFEBD5239 | S31: ok | AB31: Water flow
A32: I020 | B32: ITALY | C32: WaterMeter10 | D32: 8.53531 | E32: 39.71847 | F32: ST06 | G32: =HLOOKUP($F32,'Sensor Type Details'!$B$1:$R$4,G$1+1) -> Sensor | H32: =HLOOKUP($F32,'Sensor Type Details'!$B$1:$R$4,H$1+1) -> Maddalena | I32: =HLOOKUP($F32,'Sensor Type Details'!$B$1:$R$4,I$1+1) -> Arrow split 2 | K32: 78D800B023960387 | L32: 0101010101010101 | M32: 4A632FED0C3064F1843D734B56A26961 | S32: ok | AB32: Water flow
A33: I021 | B33: ITALY | C33: WaterMeter11 | F33: ST06 | G33: =HLOOKUP($F33,'Sensor Type Details'!$B$1:$R$4,G$1+1) -> Sensor | H33: =HLOOKUP($F33,'Sensor Type Details'!$B$1:$R$4,H$1+1) -> Maddalena | I33: =HLOOKUP($F33,'Sensor Type Details'!$B$1:$R$4,I$1+1) -> Arrow split 2 | K33: 78D800B023960388 | L33: 0101010101010101 | M33: FB973BE21492C41095240D3C30287FED | S33: ok | AB33: Water flow
A34: I022 | B34: ITALY | C34: WaterMeter12 | F34: ST06 | G34: =HLOOKUP($F34,'Sensor Type Details'!$B$1:$R$4,G$1+1) -> Sensor | H34: =HLOOKUP($F34,'Sensor Type Details'!$B$1:$R$4,H$1+1) -> Maddalena | I34: =HLOOKUP($F34,'Sensor Type Details'!$B$1:$R$4,I$1+1) -> Arrow split 2 | K34: 78D800B023960389 | L34: 0101010101010101 | M34: 4BFDB80781FB179661DA7FE5B6E43426 | S34: ok | AB34: Water flow
A35: I023 | B35: ITALY | C35: TTCyber 81238002 | D35: 8.703607 | E35: 39.9483 | F35: ST07 | G35: =HLOOKUP($F35,'Sensor Type Details'!$B$1:$R$4,G$1+1) -> Sensor | H35: =HLOOKUP($F35,'Sensor Type Details'!$B$1:$R$4,H$1+1) -> Nature4 | I35: =HLOOKUP($F35,'Sensor Type Details'!$B$1:$R$4,I$1+1) -> TTCyber | AB35: radial growth, sap flux density, tree stability, air temperature and humidity and NDVI
A36: I024 | B36: ITALY | C36: TTCyber 81238003 | D36: 8.703607 | E36: 39.9483 | F36: ST07 | G36: =HLOOKUP($F36,'Sensor Type Details'!$B$1:$R$4,G$1+1) -> Sensor | H36: =HLOOKUP($F36,'Sensor Type Details'!$B$1:$R$4,H$1+1) -> Nature4 | I36: =HLOOKUP($F36,'Sensor Type Details'!$B$1:$R$4,I$1+1) -> TTCyber | AB36: radial growth, sap flux density, tree stability, air temperature and humidity and NDVI
A37: I025 | B37: ITALY | C37: TTCyber 81238004 | D37: 8.703607 | E37: 39.9483 | F37: ST07 | G37: =HLOOKUP($F37,'Sensor Type Details'!$B$1:$R$4,G$1+1) -> Sensor | H37: =HLOOKUP($F37,'Sensor Type Details'!$B$1:$R$4,H$1+1) -> Nature4 | I37: =HLOOKUP($F37,'Sensor Type Details'!$B$1:$R$4,I$1+1) -> TTCyber | AB37: radial growth, sap flux density, tree stability, air temperature and humidity and NDVI
A38: I026 | B38: ITALY | C38: TTCyber 81238005 | D38: 8.703607 | E38: 39.9483 | F38: ST07 | G38: =HLOOKUP($F38,'Sensor Type Details'!$B$1:$R$4,G$1+1) -> Sensor | H38: =HLOOKUP($F38,'Sensor Type Details'!$B$1:$R$4,H$1+1) -> Nature4 | I38: =HLOOKUP($F38,'Sensor Type Details'!$B$1:$R$4,I$1+1) -> TTCyber | AB38: radial growth, sap flux density, tree stability, air temperature and humidity and NDVI
A39: I027 | B39: ITALY | C39: TTCyber 81238006 | D39: 8.703607 | E39: 39.9483 | F39: ST07 | G39: =HLOOKUP($F39,'Sensor Type Details'!$B$1:$R$4,G$1+1) -> Sensor | H39: =HLOOKUP($F39,'Sensor Type Details'!$B$1:$R$4,H$1+1) -> Nature4 | I39: =HLOOKUP($F39,'Sensor Type Details'!$B$1:$R$4,I$1+1) -> TTCyber | AB39: radial growth, sap flux density, tree stability, air temperature and humidity and NDVI
A40: I028 | B40: ITALY | C40: TTCyber 81238007 | D40: 8.703607 | E40: 39.9483 | F40: ST07 | G40: =HLOOKUP($F40,'Sensor Type Details'!$B$1:$R$4,G$1+1) -> Sensor | H40: =HLOOKUP($F40,'Sensor Type Details'!$B$1:$R$4,H$1+1) -> Nature4 | I40: =HLOOKUP($F40,'Sensor Type Details'!$B$1:$R$4,I$1+1) -> TTCyber | AB40: radial growth, sap flux density, tree stability, air temperature and humidity and NDVI
...

Sheet Datastream Definition
A1: Pilot | B1: Field Name | C1: Field Description | D1: Field Latitude | E1: Field Longitude | F1: Device ID | G1: Device Description | H1: Device Type | I1: Device EUI | J1: Property Key | K1: Property Name | L1: Property Description | M1: Unit Of Measurement | N1: Unit Of Measurement Symbol | O1: Datastream Name | P1: Datastream Description | Q1: Averages
A2: Demo | B2: Demo Field | C2: Demo sensors in ABI | D2: 40.727006 | E2: 8.5643235 | F2: D001 | G2: Compact and versatile environmental sensor module designed for monitoring temperature and humidity in various applications. | H2: ST01 | I2: 2cf7f1c043500183 | J2: air_temperature | K2: Air Temperature | L2: =VLOOKUP($K2,'Property names'!$A$1:$D$100,2,FALSE) -> The measure of the hotness or coldness of the air. | M2: =VLOOKUP($K2,'Property names'!$A$1:$D$100,3,FALSE) -> Degrees Celsius | N2: =VLOOKUP($K2,'Property names'!$A$1:$D$100,4,FALSE) -> ºC | O2: =SUBSTITUTE(CONCATENATE(B2,"_",F2,"_",J2)," ","_") -> Demo_Field_D001_air_temperature | P2: =CONCATENATE("The datastream containing mesures of field ",B2," by sensor ",F2," which measures ",K2,".") -> The datastream containing mesures of field Demo Field by sensor D001 which measures Air Temperature. | Q2: None
A3: Demo | B3: Demo Field | C3: Demo sensors in ABI | D3: 40.727006 | E3: 8.5643235 | F3: D001 | G3: Compact and versatile environmental sensor module designed for monitoring temperature and humidity in various applications. | H3: ST01 | I3: 2cf7f1c043500183 | J3: air_humidity | K3: Air Humidity | L3: =VLOOKUP($K3,'Property names'!$A$1:$D$100,2,FALSE) -> The amount of moisture or water vapor present in the air, often expressed as a percentage of the maximum amount the air could hold at a given temperature. | M3: =VLOOKUP($K3,'Property names'!$A$1:$D$100,3,FALSE) -> Percentage | N3: =VLOOKUP($K3,'Property names'!$A$1:$D$100,4,FALSE) -> % | O3: =SUBSTITUTE(CONCATENATE(B3,"_",F3,"_",J3)," ","_") -> Demo_Field_D001_air_humidity | P3: =CONCATENATE("The datastream containing mesures of field ",B3," by sensor ",F3," which measures ",K3,".") -> The datastream containing mesures of field Demo Field by sensor D001 which measures Air Humidity. | Q3: None
A4: Demo | B4: Demo Field | C4: Demo sensors in ABI | D4: 40.727006 | E4: 8.5643235 | F4: D001 | G4: Compact and versatile environmental sensor module designed for monitoring temperature and humidity in various applications. | H4: ST01 | I4: 2cf7f1c043500183 | J4: co2_concentration | K4: CO2 Concentration | L4: =VLOOKUP($K4,'Property names'!$A$1:$D$100,2,FALSE) -> The quantity of carbon dioxide gas present in the air, used to assess air quality and monitor environmental conditions. | M4: =VLOOKUP($K4,'Property names'!$A$1:$D$100,3,FALSE) -> Parts per million | N4: =VLOOKUP($K4,'Property names'!$A$1:$D$100,4,FALSE) -> ppm | O4: =SUBSTITUTE(CONCATENATE(B4,"_",F4,"_",J4)," ","_") -> Demo_Field_D001_co2_concentration | P4: =CONCATENATE("The datastream containing mesures of field ",B4," by sensor ",F4," which measures ",K4,".") -> The datastream containing mesures of field Demo Field by sensor D001 which measures CO2 Concentration. | Q4: None
A5: Demo | B5: Demo Field | C5: Demo sensors in ABI | D5: 40.727006 | E5: 8.5643235 | F5: D002 | G5: A sensor module for measuring soil moisture and temperature, ideal for agriculture and environmental monitoring. | H5: ST02 | I5: 2CF7F12031500017 | J5: soil_moisture | K5: Soil Moisture | L5: =VLOOKUP($K5,'Property names'!$A$1:$D$100,2,FALSE) -> The amount of moisture present in the soil, often expressed as a percentage of the maximum amount the soil could hold at a given temperature. | M5: =VLOOKUP($K5,'Property names'!$A$1:$D$100,3,FALSE) -> Percentage | N5: =VLOOKUP($K5,'Property names'!$A$1:$D$100,4,FALSE) -> % | O5: =SUBSTITUTE(CONCATENATE(B5,"_",F5,"_",J5)," ","_") -> Demo_Field_D002_soil_moisture | P5: =CONCATENATE("The datastream containing mesures of field ",B5," by sensor ",F5," which measures ",K5,".") -> The datastream containing mesures of field Demo Field by sensor D002 which measures Soil Moisture. | Q5: None
A6: Demo | B6: Demo Field | C6: Demo sensors in ABI | D6: 40.727006 | E6: 8.5643235 | F6: D002 | G6: A sensor module for measuring soil moisture and temperature, ideal for agriculture and environmental monitoring. | H6: ST02 | I6: 2CF7F12031500017 | J6: soil_temperature | K6: Soil Temperature | L6: =VLOOKUP($K6,'Property names'!$A$1:$D$100,2,FALSE) -> The measure of temperature of the soil. | M6: =VLOOKUP($K6,'Property names'!$A$1:$D$100,3,FALSE) -> Degrees Celsius | N6: =VLOOKUP($K6,'Property names'!$A$1:$D$100,4,FALSE) -> ºC | O6: =SUBSTITUTE(CONCATENATE(B6,"_",F6,"_",J6)," ","_") -> Demo_Field_D002_soil_temperature | P6: =CONCATENATE("The datastream containing mesures of field ",B6," by sensor ",F6," which measures ",K6,".") -> The datastream containing mesures of field Demo Field by sensor D002 which measures Soil Temperature. | Q6: None
A7: Demo | B7: Demo Field | C7: Demo sensors in ABI | D7: 40.727006 | E7: 8.5643235 | F7: D003 | G7: A LoRa-enabled controller for managing and controlling IoT devices, facilitating long-range wireless communication. | H7: ST03 | I7: 24e124414b106165 | J7: battery_level | K7: Battery Level | L7: =VLOOKUP($K7,'Property names'!$A$1:$D$100,2,FALSE) -> The percentage of battery level associated to the specific sensor. | M7: =VLOOKUP($K7,'Property names'!$A$1:$D$100,3,FALSE) -> Percentage | N7: =VLOOKUP($K7,'Property names'!$A$1:$D$100,4,FALSE) -> % | O7: =SUBSTITUTE(CONCATENATE(B7,"_",F7,"_",J7)," ","_") -> Demo_Field_D003_battery_level | P7: =CONCATENATE("The datastream containing mesures of field ",B7," by sensor ",F7," which measures ",K7,".") -> The datastream containing mesures of field Demo Field by sensor D003 which measures Battery Level. | Q7: None
A8: Demo | B8: Demo Field | C8: Demo sensors in ABI | D8: 40.727006 | E8: 8.5643235 | F8: D003 | G8: A LoRa-enabled controller for managing and controlling IoT devices, facilitating long-range wireless communication. | H8: ST03 | I8: 24e124414b106165 | J8: valve1_pulse | K8: Flowmeter pulses | L8: =VLOOKUP($K8,'Property names'!$A$1:$D$100,2,FALSE) -> The number of pulses read by flowmeter. Depending on flowmeter configuration it could correspond to a different number of cubic meter of water | M8: =VLOOKUP($K8,'Property names'!$A$1:$D$100,3,FALSE) -> Number of pulses | N8: =VLOOKUP($K8,'Property names'!$A$1:$D$100,4,FALSE) -> N/A | O8: =SUBSTITUTE(CONCATENATE(B8,"_",F8,"_",J8)," ","_") -> Demo_Field_D003_valve1_pulse | P8: =CONCATENATE("The datastream containing mesures of field ",B8," by sensor ",F8," which measures ",K8,".") -> The datastream containing mesures of field Demo Field by sensor D003 which measures Flowmeter pulses. | Q8: None
A9: Demo | B9: Demo Field | C9: Demo sensors in ABI | D9: 40.727006 | E9: 8.5643235 | F9: D003 | G9: A LoRa-enabled controller for managing and controlling IoT devices, facilitating long-range wireless communication. | H9: ST03 | I9: 24e124414b106165 | J9: valve1_status | K9: Valve status | L9: =VLOOKUP($K9,'Property names'!$A$1:$D$100,2,FALSE) -> The current condition of the valve controlled (opened or closed) | M9: =VLOOKUP($K9,'Property names'!$A$1:$D$100,3,FALSE) -> ON / OFF | N9: =VLOOKUP($K9,'Property names'!$A$1:$D$100,4,FALSE) -> N/A | O9: =SUBSTITUTE(CONCATENATE(B9,"_",F9,"_",J9)," ","_") -> Demo_Field_D003_valve1_status | P9: =CONCATENATE("The datastream containing mesures of field ",B9," by sensor ",F9," which measures ",K9,".") -> The datastream containing mesures of field Demo Field by sensor D003 which measures Valve status. | Q9: None
A10: Demo | B10: Demo Field | C10: Demo sensors in ABI | D10: 40.727006 | E10: 8.5643235 | F10: D003 | G10: A LoRa-enabled controller for managing and controlling IoT devices, facilitating long-range wireless communication. | H10: ST03 | I10: 24e124414b106165 | J10: valve2_pulse | K10: Flowmeter pulses | L10: =VLOOKUP($K10,'Property names'!$A$1:$D$100,2,FALSE) -> The number of pulses read by flowmeter. Depending on flowmeter configuration it could correspond to a different number of cubic meter of water | M10: =VLOOKUP($K10,'Property names'!$A$1:$D$100,3,FALSE) -> Number of pulses | N10: =VLOOKUP($K10,'Property names'!$A$1:$D$100,4,FALSE) -> N/A | O10: =SUBSTITUTE(CONCATENATE(B10,"_",F10,"_",J10)," ","_") -> Demo_Field_D003_valve2_pulse | P10: =CONCATENATE("The datastream containing mesures of field ",B10," by sensor ",F10," which measures ",K10,".") -> The datastream containing mesures of field Demo Field by sensor D003 which measures Flowmeter pulses. | Q10: None
A11: Demo | B11: Demo Field | C11: Demo sensors in ABI | D11: 40.727006 | E11: 8.5643235 | F11: D003 | G11: A LoRa-enabled controller for managing and controlling IoT devices, facilitating long-range wireless communication. | H11: ST03 | I11: 24e124414b106165 | J11: valve2_status | K11: Valve status | L11: =VLOOKUP($K11,'Property names'!$A$1:$D$100,2,FALSE) -> The current condition of the valve controlled (opened or closed) | M11: =VLOOKUP($K11,'Property names'!$A$1:$D$100,3,FALSE) -> ON / OFF | N11: =VLOOKUP($K11,'Property names'!$A$1:$D$100,4,FALSE) -> N/A | O11: =SUBSTITUTE(CONCATENATE(B11,"_",F11,"_",J11)," ","_") -> Demo_Field_D003_valve2_status | P11: =CONCATENATE("The datastream containing mesures of field ",B11," by sensor ",F11," which measures ",K11,".") -> The datastream containing mesures of field Demo Field by sensor D003 which measures Valve status. | Q11: None
A12: Demo | B12: Demo Field | C12: Demo sensors in ABI | D12: 40.727006 | E12: 8.5643235 | F12: D004 | G12: An advanced sensor capable of monitoring temperature and moisture at different depths. Useful for agronomic research activities. | H12: ST04 | I12: 3738383962376102 | J12: soil_moisture_1 | K12: Soil Moisture | L12: =VLOOKUP($K12,'Property names'!$A$1:$D$100,2,FALSE) -> The amount of moisture present in the soil, often expressed as a percentage of the maximum amount the soil could hold at a given temperature. | M12: =VLOOKUP($K12,'Property names'!$A$1:$D$100,3,FALSE) -> Percentage | N12: =VLOOKUP($K12,'Property names'!$A$1:$D$100,4,FALSE) -> % | O12: =SUBSTITUTE(CONCATENATE(B12,"_",F12,"_",J12)," ","_") -> Demo_Field_D004_soil_moisture_1 | P12: =CONCATENATE("The datastream containing mesures of field ",B12," by sensor ",F12," which measures ",K12,".") -> The datastream containing mesures of field Demo Field by sensor D004 which measures Soil Moisture. | Q12: None
A13: Demo | B13: Demo Field | C13: Demo sensors in ABI | D13: 40.727006 | E13: 8.5643235 | F13: D004 | G13: An advanced sensor capable of monitoring temperature and moisture at different depths. Useful for agronomic research activities. | H13: ST04 | I13: 3738383962376102 | J13: soil_moisture_2 | K13: Soil Moisture | L13: =VLOOKUP($K13,'Property names'!$A$1:$D$100,2,FALSE) -> The amount of moisture present in the soil, often expressed as a percentage of the maximum amount the soil could hold at a given temperature. | M13: =VLOOKUP($K13,'Property names'!$A$1:$D$100,3,FALSE) -> Percentage | N13: =VLOOKUP($K13,'Property names'!$A$1:$D$100,4,FALSE) -> % | O13: =SUBSTITUTE(CONCATENATE(B13,"_",F13,"_",J13)," ","_") -> Demo_Field_D004_soil_moisture_2 | P13: =CONCATENATE("The datastream containing mesures of field ",B13," by sensor ",F13," which measures ",K13,".") -> The datastream containing mesures of field Demo Field by sensor D004 which measures Soil Moisture. | Q13: None
... A24: Demo | B24: Demo Field | C24: Demo sensors in ABI | D24: 40.727006 | E24: 8.5643235 | F24: D004 | G24: An advanced sensor capable of monitoring temperature and moisture at different depths. Useful for agronomic research activities. | H24: ST04 | I24: 3738383962376102 | J24: soil_temperature_6 | K24: Soil Temperature | L24: =VLOOKUP($K24,'Property names'!$A$1:$D$100,2,FALSE) -> The measure of temperature of the soil. | M24: =VLOOKUP($K24,'Property names'!$A$1:$D$100,3,FALSE) -> Degrees Celsius | N24: =VLOOKUP($K24,'Property names'!$A$1:$D$100,4,FALSE) -> ºC | O24: =SUBSTITUTE(CONCATENATE(B24,"_",F24,"_",J24)," ","_") -> Demo_Field_D004_soil_temperature_6 | P24: =CONCATENATE("The datastream containing mesures of field ",B24," by sensor ",F24," which measures ",K24,".") -> The datastream containing mesures of field Demo Field by sensor D004 which measures Soil Temperature. | Q24: None
A25: Demo | B25: Demo Field | C25: Demo sensors in ABI | D25: 40.727006 | E25: 8.5643235 | F25: D005 | G25: A sensor for counting and transmitting the pulse produced by a flowmeter. | H25: =VLOOKUP(F25,'All sensors Installed'!$A$2:$I$1119,6,) -> ST05 | I25: AC1F09FFFE04E43F | J25: count | K25: Flowmeter pulses | L25: =VLOOKUP($K25,'Property names'!$A$1:$D$100,2,FALSE) -> The number of pulses read by flowmeter. Depending on flowmeter configuration it could correspond to a different number of cubic meter of water | M25: =VLOOKUP($K25,'Property names'!$A$1:$D$100,3,FALSE) -> Number of pulses | N25: =VLOOKUP($K25,'Property names'!$A$1:$D$100,4,FALSE) -> N/A | O25: =SUBSTITUTE(CONCATENATE(B25,"_",F25,"_",J25)," ","_") -> Demo_Field_D005_count | P25: =CONCATENATE("The datastream containing mesures of field ",B25," by sensor ",F25," which measures ",K25,".") -> The datastream containing mesures of field Demo Field by sensor D005 which measures Flowmeter pulses. | Q25: None
A26: Demo | B26: Demo Field | C26: Demo sensors in ABI | D26: 40.727006 | E26: 8.5643235 | F26: D005 | G26: A sensor for counting and transmitting the pulse produced by a flowmeter. | H26: =VLOOKUP(F26,'All sensors Installed'!$A$2:$I$1119,6,) -> ST05 | I26: AC1F09FFFE04E43F | J26: leak | K26: Leak warning | L26: =VLOOKUP($K26,'Property names'!$A$1:$D$100,2,FALSE) -> A warning in case of water leak detected | M26: =VLOOKUP($K26,'Property names'!$A$1:$D$100,3,FALSE) -> True / False | N26: =VLOOKUP($K26,'Property names'!$A$1:$D$100,4,FALSE) -> N/A | O26: =SUBSTITUTE(CONCATENATE(B26,"_",F26,"_",J26)," ","_") -> Demo_Field_D005_leak | P26: =CONCATENATE("The datastream containing mesures of field ",B26," by sensor ",F26," which measures ",K26,".") -> The datastream containing mesures of field Demo Field by sensor D005 which measures Leak warning. | Q26: None
A27: Demo | B27: Demo Field | C27: Demo sensors in ABI | D27: 40.727006 | E27: 8.5643235 | F27: D005 | G27: A sensor for counting and transmitting the pulse produced by a flowmeter. | H27: =VLOOKUP(F27,'All sensors Installed'!$A$2:$I$1119,6,) -> ST05 | I27: AC1F09FFFE04E43F | J27: system_voltage | K27: Battery Voltage | L27: =VLOOKUP($K27,'Property names'!$A$1:$D$100,2,FALSE) -> The electrical potential in a battery, indicating its charge level. | M27: =VLOOKUP($K27,'Property names'!$A$1:$D$100,3,FALSE) -> Millivolts | N27: =VLOOKUP($K27,'Property names'!$A$1:$D$100,4,FALSE) -> mV | O27: =SUBSTITUTE(CONCATENATE(B27,"_",F27,"_",J27)," ","_") -> Demo_Field_D005_system_voltage | P27: =CONCATENATE("The datastream containing mesures of field ",B27," by sensor ",F27," which measures ",K27,".") -> The datastream containing mesures of field Demo Field by sensor D005 which measures Battery Voltage. | Q27: None
A28: Italy | B28: Torresan | C28: Sensors owned by UNISS | D28: 39.77597 | E28: 8.54903 | F28: I001 | G28: An advanced sensor capable of monitoring temperature and moisture at different depths. Useful for agronomic research activities. | H28: =VLOOKUP(F28,'All sensors Installed'!$A$2:$K$1119,6,) -> ST04 | I28: =VLOOKUP(F28,'All sensors Installed'!$A$2:$K$1119,11,) -> AC1F09FFFE04E48A | J28: soil_moisture_1 | K28: Soil Moisture | L28: =VLOOKUP($K28,'Property names'!$A$1:$D$100,2,FALSE) -> The amount of moisture present in the soil, often expressed as a percentage of the maximum amount the soil could hold at a given temperature. | M28: =VLOOKUP($K28,'Property names'!$A$1:$D$100,3,FALSE) -> Percentage | N28: =VLOOKUP($K28,'Property names'!$A$1:$D$100,4,FALSE) -> % | O28: =SUBSTITUTE(CONCATENATE(B28,"_",F28,"_",J28)," ","_") -> Torresan_I001_soil_moisture_1 | P28: =CONCATENATE("The datastream containing mesures of field ",B28," by sensor ",F28," which measures ",K28,".") -> The datastream containing mesures of field Torresan by sensor I001 which measures Soil Moisture. | Q28: None
A29: Italy | B29: Torresan | C29: Sensors owned by UNISS | D29: 39.77597 | E29: 8.54903 | F29: I001 | G29: An advanced sensor capable of monitoring temperature and moisture at different depths. Useful for agronomic research activities. | H29: =VLOOKUP(F29,'All sensors Installed'!$A$2:$K$1119,6,) -> ST04 | I29: =VLOOKUP(F29,'All sensors Installed'!$A$2:$K$1119,11,) -> AC1F09FFFE04E48A | J29: soil_moisture_2 | K29: Soil Moisture | L29: =VLOOKUP($K29,'Property names'!$A$1:$D$100,2,FALSE) -> The amount of moisture present in the soil, often expressed as a percentage of the maximum amount the soil could hold at a given temperature. | M29: =VLOOKUP($K29,'Property names'!$A$1:$D$100,3,FALSE) -> Percentage | N29: =VLOOKUP($K29,'Property names'!$A$1:$D$100,4,FALSE) -> % | O29: =SUBSTITUTE(CONCATENATE(B29,"_",F29,"_",J29)," ","_") -> Torresan_I001_soil_moisture_2 | P29: =CONCATENATE("The datastream containing mesures of field ",B29," by sensor ",F29," which measures ",K29,".") -> The datastream containing mesures of field Torresan by sensor I001 which measures Soil Moisture. | Q29: None
A30: Italy | B30: Torresan | C30: Sensors owned by UNISS | D30: 39.77597 | E30: 8.54903 | F30: I001 | G30: An advanced sensor capable of monitoring temperature and moisture at different depths. Useful for agronomic research activities. | H30: =VLOOKUP(F30,'All sensors Installed'!$A$2:$K$1119,6,) -> ST04 | I30: =VLOOKUP(F30,'All sensors Installed'!$A$2:$K$1119,11,) -> AC1F09FFFE04E48A | J30: soil_moisture_3 | K30: Soil Moisture | L30: =VLOOKUP($K30,'Property names'!$A$1:$D$100,2,FALSE) -> The amount of moisture present in the soil, often expressed as a percentage of the maximum amount the soil could hold at a given temperature. | M30: =VLOOKUP($K30,'Property names'!$A$1:$D$100,3,FALSE) -> Percentage | N30: =VLOOKUP($K30,'Property names'!$A$1:$D$100,4,FALSE) -> % | O30: =SUBSTITUTE(CONCATENATE(B30,"_",F30,"_",J30)," ","_") -> Torresan_I001_soil_moisture_3 | P30: =CONCATENATE("The datastream containing mesures of field ",B30," by sensor ",F30," which measures ",K30,".") -> The datastream containing mesures of field Torresan by sensor I001 which measures Soil Moisture. | Q30: None
A31: Italy | B31: Torresan | C31: Sensors owned by UNISS | D31: 39.77597 | E31: 8.54903 | F31: I001 | G31: An advanced sensor capable of monitoring temperature and moisture at different depths. Useful for agronomic research activities. | H31: =VLOOKUP(F31,'All sensors Installed'!$A$2:$K$1119,6,) -> ST04 | I31: =VLOOKUP(F31,'All sensors Installed'!$A$2:$K$1119,11,) -> AC1F09FFFE04E48A | J31: soil_moisture_4 | K31: Soil Moisture | L31: =VLOOKUP($K31,'Property names'!$A$1:$D$100,2,FALSE) -> The amount of moisture present in the soil, often expressed as a percentage of the maximum amount the soil could hold at a given temperature. | M31: =VLOOKUP($K31,'Property names'!$A$1:$D$100,3,FALSE) -> Percentage | N31: =VLOOKUP($K31,'Property names'!$A$1:$D$100,4,FALSE) -> % | O31: =SUBSTITUTE(CONCATENATE(B31,"_",F31,"_",J31)," ","_") -> Torresan_I001_soil_moisture_4 | P31: =CONCATENATE("The datastream containing mesures of field ",B31," by sensor ",F31," which measures ",K31,".") -> The datastream containing mesures of field Torresan by sensor I001 which measures Soil Moisture. | Q31: None
A32: Italy | B32: Torresan | C32: Sensors owned by UNISS | D32: 39.77597 | E32: 8.54903 | F32: I001 | G32: An advanced sensor capable of monitoring temperature and moisture at different depths. Useful for agronomic research activities. | H32: =VLOOKUP(F32,'All sensors Installed'!$A$2:$K$1119,6,) -> ST04 | I32: =VLOOKUP(F32,'All sensors Installed'!$A$2:$K$1119,11,) -> AC1F09FFFE04E48A | J32: soil_moisture_5 | K32: Soil Moisture | L32: =VLOOKUP($K32,'Property names'!$A$1:$D$100,2,FALSE) -> The amount of moisture present in the soil, often expressed as a percentage of the maximum amount the soil could hold at a given temperature. | M32: =VLOOKUP($K32,'Property names'!$A$1:$D$100,3,FALSE) -> Percentage | N32: =VLOOKUP($K32,'Property names'!$A$1:$D$100,4,FALSE) -> % | O32: =SUBSTITUTE(CONCATENATE(B32,"_",F32,"_",J32)," ","_") -> Torresan_I001_soil_moisture_5 | P32: =CONCATENATE("The datastream containing mesures of field ",B32," by sensor ",F32," which measures ",K32,".") -> The datastream containing mesures of field Torresan by sensor I001 which measures Soil Moisture. | Q32: None
A33: Italy | B33: Torresan | C33: Sensors owned by UNISS | D33: 39.77597 | E33: 8.54903 | F33: I001 | G33: An advanced sensor capable of monitoring temperature and moisture at different depths. Useful for agronomic research activities. | H33: =VLOOKUP(F33,'All sensors Installed'!$A$2:$K$1119,6,) -> ST04 | I33: =VLOOKUP(F33,'All sensors Installed'!$A$2:$K$1119,11,) -> AC1F09FFFE04E48A | J33: soil_moisture_6 | K33: Soil Moisture | L33: =VLOOKUP($K33,'Property names'!$A$1:$D$100,2,FALSE) -> The amount of moisture present in the soil, often expressed as a percentage of the maximum amount the soil could hold at a given temperature. | M33: =VLOOKUP($K33,'Property names'!$A$1:$D$100,3,FALSE) -> Percentage | N33: =VLOOKUP($K33,'Property names'!$A$1:$D$100,4,FALSE) -> % | O33: =SUBSTITUTE(CONCATENATE(B33,"_",F33,"_",J33)," ","_") -> Torresan_I001_soil_moisture_6 | P33: =CONCATENATE("The datastream containing mesures of field ",B33," by sensor ",F33," which measures ",K33,".") -> The datastream containing mesures of field Torresan by sensor I001 which measures Soil Moisture. | Q33: None
A34: Italy | B34: Torresan | C34: Sensors owned by UNISS | D34: 39.77597 | E34: 8.54903 | F34: I001 | G34: An advanced sensor capable of monitoring temperature and moisture at different depths. Useful for agronomic research activities. | H34: =VLOOKUP(F34,'All sensors Installed'!$A$2:$K$1119,6,) -> ST04 | I34: =VLOOKUP(F34,'All sensors Installed'!$A$2:$K$1119,11,) -> AC1F09FFFE04E48A | J34: ambient_temperature | K34: Air Temperature | L34: =VLOOKUP($K34,'Property names'!$A$1:$D$100,2,FALSE) -> The measure of the hotness or coldness of the air. | M34: =VLOOKUP($K34,'Property names'!$A$1:$D$100,3,FALSE) -> Degrees Celsius | N34: =VLOOKUP($K34,'Property names'!$A$1:$D$100,4,FALSE) -> ºC | O34: =SUBSTITUTE(CONCATENATE(B34,"_",F34,"_",J34)," ","_") -> Torresan_I001_ambient_temperature | P34: =CONCATENATE("The datastream containing mesures of field ",B34," by sensor ",F34," which measures ",K34,".") -> The datastream containing mesures of field Torresan by sensor I001 which measures Air Temperature. | Q34: None
A35: Italy | B35: Torresan | C35: Sensors owned by UNISS | D35: 39.77597 | E35: 8.54903 | F35: I001 | G35: An advanced sensor capable of monitoring temperature and moisture at different depths. Useful for agronomic research activities. | H35: =VLOOKUP(F35,'All sensors Installed'!$A$2:$K$1119,6,) -> ST04 | I35: =VLOOKUP(F35,'All sensors Installed'!$A$2:$K$1119,11,) -> AC1F09FFFE04E48A | J35: soil_temperature_1 | K35: Soil Temperature | L35: =VLOOKUP($K35,'Property names'!$A$1:$D$100,2,FALSE) -> The measure of temperature of the soil. | M35: =VLOOKUP($K35,'Property names'!$A$1:$D$100,3,FALSE) -> Degrees Celsius | N35: =VLOOKUP($K35,'Property names'!$A$1:$D$100,4,FALSE) -> ºC | O35: =SUBSTITUTE(CONCATENATE(B35,"_",F35,"_",J35)," ","_") -> Torresan_I001_soil_temperature_1 | P35: =CONCATENATE("The datastream containing mesures of field ",B35," by sensor ",F35," which measures ",K35,".") -> The datastream containing mesures of field Torresan by sensor I001 which measures Soil Temperature. | Q35: None
A36: Italy | B36: Torresan | C36: Sensors owned by UNISS | D36: 39.77597 | E36: 8.54903 | F36: I001 | G36: An advanced sensor capable of monitoring temperature and moisture at different depths. Useful for agronomic research activities. | H36: =VLOOKUP(F36,'All sensors Installed'!$A$2:$K$1119,6,) -> ST04 | I36: =VLOOKUP(F36,'All sensors Installed'!$A$2:$K$1119,11,) -> AC1F09FFFE04E48A | J36: soil_temperature_2 | K36: Soil Temperature | L36: =VLOOKUP($K36,'Property names'!$A$1:$D$100,2,FALSE) -> The measure of temperature of the soil. | M36: =VLOOKUP($K36,'Property names'!$A$1:$D$100,3,FALSE) -> Degrees Celsius | N36: =VLOOKUP($K36,'Property names'!$A$1:$D$100,4,FALSE) -> ºC | O36: =SUBSTITUTE(CONCATENATE(B36,"_",F36,"_",J36)," ","_") -> Torresan_I001_soil_temperature_2 | P36: =CONCATENATE("The datastream containing mesures of field ",B36," by sensor ",F36," which measures ",K36,".") -> The datastream containing mesures of field Torresan by sensor I001 which measures Soil Temperature. | Q36: None
A37: Italy | B37: Torresan | C37: Sensors owned by UNISS | D37: 39.77597 | E37: 8.54903 | F37: I001 | G37: An advanced sensor capable of monitoring temperature and moisture at different depths. Useful for agronomic research activities. | H37: =VLOOKUP(F37,'All sensors Installed'!$A$2:$K$1119,6,) -> ST04 | I37: =VLOOKUP(F37,'All sensors Installed'!$A$2:$K$1119,11,) -> AC1F09FFFE04E48A | J37: soil_temperature_3 | K37: Soil Temperature | L37: =VLOOKUP($K37,'Property names'!$A$1:$D$100,2,FALSE) -> The measure of temperature of the soil. | M37: =VLOOKUP($K37,'Property names'!$A$1:$D$100,3,FALSE) -> Degrees Celsius | N37: =VLOOKUP($K37,'Property names'!$A$1:$D$100,4,FALSE) -> ºC | O37: =SUBSTITUTE(CONCATENATE(B37,"_",F37,"_",J37)," ","_") -> Torresan_I001_soil_temperature_3 | P37: =CONCATENATE("The datastream containing mesures of field ",B37," by sensor ",F37," which measures ",K37,".") -> The datastream containing mesures of field Torresan by sensor I001 which measures Soil Temperature. | Q37: None
A38: Italy | B38: Torresan | C38: Sensors owned by UNISS | D38: 39.77597 | E38: 8.54903 | F38: I001 | G38: An advanced sensor capable of monitoring temperature and moisture at different depths. Useful for agronomic research activities. | H38: =VLOOKUP(F38,'All sensors Installed'!$A$2:$K$1119,6,) -> ST04 | I38: =VLOOKUP(F38,'All sensors Installed'!$A$2:$K$1119,11,) -> AC1F09FFFE04E48A | J38: soil_temperature_4 | K38: Soil Temperature | L38: =VLOOKUP($K38,'Property names'!$A$1:$D$100,2,FALSE) -> The measure of temperature of the soil. | M38: =VLOOKUP($K38,'Property names'!$A$1:$D$100,3,FALSE) -> Degrees Celsius | N38: =VLOOKUP($K38,'Property names'!$A$1:$D$100,4,FALSE) -> ºC | O38: =SUBSTITUTE(CONCATENATE(B38,"_",F38,"_",J38)," ","_") -> Torresan_I001_soil_temperature_4 | P38: =CONCATENATE("The datastream containing mesures of field ",B38," by sensor ",F38," which measures ",K38,".") -> The datastream containing mesures of field Torresan by sensor I001 which measures Soil Temperature. | Q38: None
A39: Italy | B39: Torresan | C39: Sensors owned by UNISS | D39: 39.77597 | E39: 8.54903 | F39: I001 | G39: An advanced sensor capable of monitoring temperature and moisture at different depths. Useful for agronomic research activities. | H39: =VLOOKUP(F39,'All sensors Installed'!$A$2:$K$1119,6,) -> ST04 | I39: =VLOOKUP(F39,'All sensors Installed'!$A$2:$K$1119,11,) -> AC1F09FFFE04E48A | J39: soil_temperature_5 | K39: Soil Temperature | L39: =VLOOKUP($K39,'Property names'!$A$1:$D$100,2,FALSE) -> The measure of temperature of the soil. | M39: =VLOOKUP($K39,'Property names'!$A$1:$D$100,3,FALSE) -> Degrees Celsius | N39: =VLOOKUP($K39,'Property names'!$A$1:$D$100,4,FALSE) -> ºC | O39: =SUBSTITUTE(CONCATENATE(B39,"_",F39,"_",J39)," ","_") -> Torresan_I001_soil_temperature_5 | P39: =CONCATENATE("The datastream containing mesures of field ",B39," by sensor ",F39," which measures ",K39,".") -> The datastream containing mesures of field Torresan by sensor I001 which measures Soil Temperature. | Q39: None
... A157: Italy | B157: Pivetta | C157: Sensors owned by UNISS | D157: 39.71772 | E157: 8.53533 | F157: I010 | G157: An advanced sensor capable of monitoring temperature and moisture at different depths. Useful for agronomic research activities. | H157: =VLOOKUP(F157,'All sensors Installed'!$A$2:$K$1119,6,) -> ST04 | I157: =VLOOKUP(F157,'All sensors Installed'!$A$2:$K$1119,11,) -> AC1F09FFFE04E312 | J157: soil_temperature_6 | K157: Soil Temperature | L157: =VLOOKUP($K157,'Property names'!$A$1:$D$100,2,FALSE) -> The measure of temperature of the soil. | M157: =VLOOKUP($K157,'Property names'!$A$1:$D$100,3,FALSE) -> Degrees Celsius | N157: =VLOOKUP($K157,'Property names'!$A$1:$D$100,4,FALSE) -> ºC | O157: =SUBSTITUTE(CONCATENATE(B157,"_",F157,"_",J157)," ","_") -> Pivetta_I010_soil_temperature_6 | P157: =CONCATENATE("The datastream containing mesures of field ",B157," by sensor ",F157," which measures ",K157,".") -> The datastream containing mesures of field Pivetta by sensor I010 which measures Soil Temperature. | Q157: None
A158: Italy | B158: Centro Aziendale | C158: Sensors owned by UNISS | D158: 39.94489 | E158: 8.69725 | F158: I011 | G158: Water flow meter equipped with LoRaWAN transmitter | H158: ST06 | I158: =VLOOKUP(F158,'All sensors Installed'!$A$2:$K$1119,11,) -> 78D800B023960378 | J158: water_count | K158: Flowmeter pulses | L158: =VLOOKUP($K158,'Property names'!$A$1:$D$100,2,FALSE) -> The number of pulses read by flowmeter. Depending on flowmeter configuration it could correspond to a different number of cubic meter of water | M158: =VLOOKUP($K158,'Property names'!$A$1:$D$100,3,FALSE) -> Number of pulses | N158: =VLOOKUP($K158,'Property names'!$A$1:$D$100,4,FALSE) -> N/A | O158: =SUBSTITUTE(CONCATENATE(B158,"_",F158,"_",J158)," ","_") -> Centro_Aziendale_I011_water_count | P158: =CONCATENATE("The datastream containing mesures of field ",B158," by sensor ",F158," which measures ",K158,".") -> The datastream containing mesures of field Centro Aziendale by sensor I011 which measures Flowmeter pulses. | Q158: None
A159: Italy | B159: Centro Aziendale | C159: Sensors owned by UNISS | D159: 39.94489 | E159: 8.69725 | F159: I011 | G159: Water flow meter equipped with LoRaWAN transmitter | H159: ST06 | I159: =VLOOKUP(F159,'All sensors Installed'!$A$2:$K$1119,11,) -> 78D800B023960378 | J159: water_count_m3 | K159: Water count m^3 | L159: =VLOOKUP($K159,'Property names'!$A$1:$D$100,2,FALSE) -> Incremental counting of water passed by the flowmeter | M159: =VLOOKUP($K159,'Property names'!$A$1:$D$100,3,FALSE) -> Cubic meters | N159: =VLOOKUP($K159,'Property names'!$A$1:$D$100,4,FALSE) -> m^3 | O159: =SUBSTITUTE(CONCATENATE(B159,"_",F159,"_",J159)," ","_") -> Centro_Aziendale_I011_water_count_m3 | P159: =CONCATENATE("The datastream containing mesures of field ",B159," by sensor ",F159," which measures ",K159,".") -> The datastream containing mesures of field Centro Aziendale by sensor I011 which measures Water count m^3. | Q159: None
A160: Italy | B160: Mazzacaddeo | C160: Sensors owned by UNISS | D160: 39.94869 | E160: 8.680194 | F160: I013 | G160: Water flow meter equipped with LoRaWAN transmitter | H160: ST06 | I160: =VLOOKUP(F160,'All sensors Installed'!$A$2:$K$1119,11,) -> 78D800B023960380 | J160: water_count | K160: Flowmeter pulses | L160: =VLOOKUP($K160,'Property names'!$A$1:$D$100,2,FALSE) -> The number of pulses read by flowmeter. Depending on flowmeter configuration it could correspond to a different number of cubic meter of water | M160: =VLOOKUP($K160,'Property names'!$A$1:$D$100,3,FALSE) -> Number of pulses | N160: =VLOOKUP($K160,'Property names'!$A$1:$D$100,4,FALSE) -> N/A | O160: =SUBSTITUTE(CONCATENATE(B160,"_",F160,"_",J160)," ","_") -> Mazzacaddeo_I013_water_count | P160: =CONCATENATE("The datastream containing mesures of field ",B160," by sensor ",F160," which measures ",K160,".") -> The datastream containing mesures of field Mazzacaddeo by sensor I013 which measures Flowmeter pulses. | Q160: None
A161: Italy | B161: Mazzacaddeo | C161: Sensors owned by UNISS | D161: 39.94869 | E161: 8.680194 | F161: I013 | G161: Water flow meter equipped with LoRaWAN transmitter | H161: ST06 | I161: =VLOOKUP(F161,'All sensors Installed'!$A$2:$K$1119,11,) -> 78D800B023960380 | J161: water_count_m3 | K161: Water count m^3 | L161: =VLOOKUP($K161,'Property names'!$A$1:$D$100,2,FALSE) -> Incremental counting of water passed by the flowmeter | M161: =VLOOKUP($K161,'Property names'!$A$1:$D$100,3,FALSE) -> Cubic meters | N161: =VLOOKUP($K161,'Property names'!$A$1:$D$100,4,FALSE) -> m^3 | O161: =SUBSTITUTE(CONCATENATE(B161,"_",F161,"_",J161)," ","_") -> Mazzacaddeo_I013_water_count_m3 | P161: =CONCATENATE("The datastream containing mesures of field ",B161," by sensor ",F161," which measures ",K161,".") -> The datastream containing mesures of field Mazzacaddeo by sensor I013 which measures Water count m^3. | Q161: None
A162: Italy | B162: Perra 2 | C162: Sensors owned by UNISS | D162: 39.94853 | E162: 8.681917 | F162: I014 | G162: Water flow meter equipped with LoRaWAN transmitter | H162: ST06 | I162: =VLOOKUP(F162,'All sensors Installed'!$A$2:$K$1119,11,) -> 78D800B023960381 | J162: water_count | K162: Flowmeter pulses | L162: =VLOOKUP($K162,'Property names'!$A$1:$D$100,2,FALSE) -> The number of pulses read by flowmeter. Depending on flowmeter configuration it could correspond to a different number of cubic meter of water | M162: =VLOOKUP($K162,'Property names'!$A$1:$D$100,3,FALSE) -> Number of pulses | N162: =VLOOKUP($K162,'Property names'!$A$1:$D$100,4,FALSE) -> N/A | O162: =SUBSTITUTE(CONCATENATE(B162,"_",F162,"_",J162)," ","_") -> Perra_2_I014_water_count | P162: =CONCATENATE("The datastream containing mesures of field ",B162," by sensor ",F162," which measures ",K162,".") -> The datastream containing mesures of field Perra 2 by sensor I014 which measures Flowmeter pulses. | Q162: None
A163: Italy | B163: Perra 2 | C163: Sensors owned by UNISS | D163: 39.94853 | E163: 8.681917 | F163: I014 | G163: Water flow meter equipped with LoRaWAN transmitter | H163: ST06 | I163: =VLOOKUP(F163,'All sensors Installed'!$A$2:$K$1119,11,) -> 78D800B023960381 | J163: water_count_m3 | K163: Water count m^3 | L163: =VLOOKUP($K163,'Property names'!$A$1:$D$100,2,FALSE) -> Incremental counting of water passed by the flowmeter | M163: =VLOOKUP($K163,'Property names'!$A$1:$D$100,3,FALSE) -> Cubic meters | N163: =VLOOKUP($K163,'Property names'!$A$1:$D$100,4,FALSE) -> m^3 | O163: =SUBSTITUTE(CONCATENATE(B163,"_",F163,"_",J163)," ","_") -> Perra_2_I014_water_count_m3 | P163: =CONCATENATE("The datastream containing mesures of field ",B163," by sensor ",F163," which measures ",K163,".") -> The datastream containing mesures of field Perra 2 by sensor I014 which measures Water count m^3. | Q163: None
A164: Italy | B164: Torresan | C164: Sensors owned by UNISS | D164: 39.77597 | E164: 8.54903 | F164: I015 | G164: Water flow meter equipped with LoRaWAN transmitter | H164: ST06 | I164: =VLOOKUP(F164,'All sensors Installed'!$A$2:$K$1119,11,) -> 78D800B023960382 | J164: water_count | K164: Flowmeter pulses | L164: =VLOOKUP($K164,'Property names'!$A$1:$D$100,2,FALSE) -> The number of pulses read by flowmeter. Depending on flowmeter configuration it could correspond to a different number of cubic meter of water | M164: =VLOOKUP($K164,'Property names'!$A$1:$D$100,3,FALSE) -> Number of pulses | N164: =VLOOKUP($K164,'Property names'!$A$1:$D$100,4,FALSE) -> N/A | O164: =SUBSTITUTE(CONCATENATE(B164,"_",F164,"_",J164)," ","_") -> Torresan_I015_water_count | P164: =CONCATENATE("The datastream containing mesures of field ",B164," by sensor ",F164," which measures ",K164,".") -> The datastream containing mesures of field Torresan by sensor I015 which measures Flowmeter pulses. | Q164: None
A165: Italy | B165: Torresan | C165: Sensors owned by UNISS | D165: 39.77597 | E165: 8.54903 | F165: I015 | G165: Water flow meter equipped with LoRaWAN transmitter | H165: ST06 | I165: =VLOOKUP(F165,'All sensors Installed'!$A$2:$K$1119,11,) -> 78D800B023960382 | J165: water_count_m3 | K165: Water count m^3 | L165: =VLOOKUP($K165,'Property names'!$A$1:$D$100,2,FALSE) -> Incremental counting of water passed by the flowmeter | M165: =VLOOKUP($K165,'Property names'!$A$1:$D$100,3,FALSE) -> Cubic meters | N165: =VLOOKUP($K165,'Property names'!$A$1:$D$100,4,FALSE) -> m^3 | O165: =SUBSTITUTE(CONCATENATE(B165,"_",F165,"_",J165)," ","_") -> Torresan_I015_water_count_m3 | P165: =CONCATENATE("The datastream containing mesures of field ",B165," by sensor ",F165," which measures ",K165,".") -> The datastream containing mesures of field Torresan by sensor I015 which measures Water count m^3. | Q165: None
A166: Italy | B166: Torresan | C166: Sensors owned by UNISS | D166: 39.77614 | E166: 8.5485 | F166: I016 | G166: Water flow meter equipped with LoRaWAN transmitter | H166: ST06 | I166: =VLOOKUP(F166,'All sensors Installed'!$A$2:$K$1119,11,) -> 78D800B023960383 | J166: water_count | K166: Flowmeter pulses | L166: =VLOOKUP($K166,'Property names'!$A$1:$D$100,2,FALSE) -> The number of pulses read by flowmeter. Depending on flowmeter configuration it could correspond to a different number of cubic meter of water | M166: =VLOOKUP($K166,'Property names'!$A$1:$D$100,3,FALSE) -> Number of pulses | N166: =VLOOKUP($K166,'Property names'!$A$1:$D$100,4,FALSE) -> N/A | O166: =SUBSTITUTE(CONCATENATE(B166,"_",F166,"_",J166)," ","_") -> Torresan_I016_water_count | P166: =CONCATENATE("The datastream containing mesures of field ",B166," by sensor ",F166," which measures ",K166,".") -> The datastream containing mesures of field Torresan by sensor I016 which measures Flowmeter pulses. | Q166: None
A167: Italy | B167: Torresan | C167: Sensors owned by UNISS | D167: 39.77614 | E167: 8.5485 | F167: I016 | G167: Water flow meter equipped with LoRaWAN transmitter | H167: ST06 | I167: =VLOOKUP(F167,'All sensors Installed'!$A$2:$K$1119,11,) -> 78D800B023960383 | J167: water_count_m3 | K167: Water count m^3 | L167: =VLOOKUP($K167,'Property names'!$A$1:$D$100,2,FALSE) -> Incremental counting of water passed by the flowmeter | M167: =VLOOKUP($K167,'Property names'!$A$1:$D$100,3,FALSE) -> Cubic meters | N167: =VLOOKUP($K167,'Property names'!$A$1:$D$100,4,FALSE) -> m^3 | O167: =SUBSTITUTE(CONCATENATE(B167,"_",F167,"_",J167)," ","_") -> Torresan_I016_water_count_m3 | P167: =CONCATENATE("The datastream containing mesures of field ",B167," by sensor ",F167," which measures ",K167,".") -> The datastream containing mesures of field Torresan by sensor I016 which measures Water count m^3. | Q167: None
...

Sheet Sensor Type Details
A1: DEVICE TYPE | B1: GT1 | C1: ST01 | D1: ST02 | E1: ST03 | F1: ST04 | G1: ST05 | H1: ST06 | I1: ST07 | J1: ST08 | K1: ST09 | L1: ST10 | M1: ST11 | N1: ST12 | O1: ST13 | P1: ST14 | Q1: ST15
A2: FUNCTION | B2: Gateway | C2: Sensor | D2: Sensor | E2: Sensor | F2: Sensor | G2: Sensor | H2: Sensor | I2: Sensor | J2: Weather station | K2: Sensor | L2: Weather station | M2: Weather station | N2: Sensor | O2: Sensore | P2: Sensore | Q2: Weather station - wind module
A3: BRAND | B3: Rackwireless | C3: Seeeds | D3: Seeeds | E3: Milesight | F3: IQNexus | G3: IQNexus | H3: Maddalena | I3: Nature4 | J3: PrimoPrincipio | K3: VanWalt | L3: No-lora | M3: No-lora | N3: Shendga | O3: SENSOTERRA | P3: Shangai BOQU | Q3: PrimoPrincipio
A4: MODEL | B4: RAK7240 | C4: SenseCAPS2103 | D4: SenseCAP Soil Moisture and Temperature | E4: LoRa_Controlle-UC511 | F4: SenProbe - 3B-LR12 | G4: SenPulse-PCT-3A-LR-S | H4: Arrow split 2 | I4: TTCyber | J4: Quido - basic module | K4: DataHub | L4: Weather station - old | M4: Weather station - new | N4: Bulk water meter | O4: Multi Depth Soil Moisture Sensor | P4: Multi-parameter Analyzer | Q4: Quido - wind module
A5: Note | C5: Demo | D5: Demo | E5: Demo | I5: Italy | J5: Italy | L5: Jordan | M5: Jordan | N5: Jordan | O5: Jordan | P5: Jordan | Q5: Italy
A6: Message 1 | B6: Timestamp | C6: Air_Humidity | D6: Soil_Moisture | E6: battery_level | F6: Hmd Field 1 | G6: Count | H6: prev_eod_read | I6: Timestamp | J6: battery | Q6: battery
B7: GatewayEui | C7: Air_Temperature | D7: Soil_Temperature | E7: valve1_pulse | F7: Hmd Field 2 | G7: Leak | H7: prev_base_read | I7: SapFlow | J7: solar_radiation | Q7: wind_mean
B8: DevAddr | C8: CO2 | D8: CRC | E8: valve1_status | F8: Hmd Field 3 | G8: Quarte of Day | H8: delta_read_1 | I8: NDVI | J8: air_temperature | Q8: wind_max
B9: DevEui | C9: Fport | D9: battery_level | E9: valve2_pulse | F9: Hmd Field 4 | G9: System Voltage | H9: delta_read_2 | I9: RadialGrowth | J9: air_humidity | Q9: wind_dir
B10: Frequency | C10: MType | E10: valve2_status | F10: Hmd Field 5 | G10: Type | H10: delta_read_3 | I10: AirTemperature | J10: cumulative_precipitation
B11: MType | C11: Mic | F11: Hmd Field 6 | H11: delta_read_4 | I11: AirHumidity | J11: leaf_wetting
B12: SpreadingFactor | C12: Rssi | F12: Sistem Voltage | H12: delta_read_5 | I12: TrunkInclination
B13: FPort | C13: Snr | H13: delta_read_6 | I13: BatteryLevel
B14: FCnt | F14: Type | H14: delta_read_7
B15: CodeRate | H15: delta_read_8
B16: DataRate | H16: delta_read_9
B17: Bandwidth | H17: delta_read_10
H18: delta_read_11
A19: Message 2 | F19: Ambient Tmp
F20: Tmp Field 1
F21: Tmp Field 2
F22: Tmp Field 3
F23: Tmp Field 4
F24: Tmp Field 5
F25: Tmp Field 6
F26: Sistem Voltage
F27: Time Stamp
F28: Type
A31: Q.ty of measurment | B31: =COUNTA(B6:B30) -> 12 | C31: =COUNTA(C6:C30) -> 8 | D31: =COUNTA(D6:D30) -> 4 | E31: =COUNTA(E6:E30) -> 5 | F31: =COUNTA(F6:F30) -> 18 | G31: =COUNTA(G6:G30) -> 5 | I31: =COUNTA(I6:I30) -> 8
A32: Q.ty of devices
A33: Demo | B33: =COUNTIFS('All sensors Installed'!$B:$B,$A33,'All sensors Installed'!$F:$F,B$1) -> 1 | C33: =COUNTIFS('All sensors Installed'!$B:$B,$A33,'All sensors Installed'!$F:$F,C$1) -> 1 | D33: =COUNTIFS('All sensors Installed'!$B:$B,$A33,'All sensors Installed'!$F:$F,D$1) -> 1 | E33: =COUNTIFS('All sensors Installed'!$B:$B,$A33,'All sensors Installed'!$F:$F,E$1) -> 1 | F33: =COUNTIFS('All sensors Installed'!$B:$B,$A33,'All sensors Installed'!$F:$F,F$1) -> 1 | G33: =COUNTIFS('All sensors Installed'!$B:$B,$A33,'All sensors Installed'!$F:$F,G$1) -> 1 | H33: =COUNTIFS('All sensors Installed'!$B:$B,$A33,'All sensors Installed'!$F:$F,H$1) -> 0 | I33: =COUNTIFS('All sensors Installed'!$B:$B,$A33,'All sensors Installed'!$F:$F,I$1) -> 0 | ... P33: =COUNTIFS('All sensors Installed'!$B:$B,$A33,'All sensors Installed'!$F:$F,P$1) -> 0
A34: ITALY | B34: =COUNTIFS('All sensors Installed'!$B:$B,$A34,'All sensors Installed'!$F:$F,B$1) -> 2 | C34: =COUNTIFS('All sensors Installed'!$B:$B,$A34,'All sensors Installed'!$F:$F,C$1) -> 0 | D34: =COUNTIFS('All sensors Installed'!$B:$B,$A34,'All sensors Installed'!$F:$F,D$1) -> 0 | E34: =COUNTIFS('All sensors Installed'!$B:$B,$A34,'All sensors Installed'!$F:$F,E$1) -> 0 | F34: =COUNTIFS('All sensors Installed'!$B:$B,$A34,'All sensors Installed'!$F:$F,F$1) -> 10 | G34: =COUNTIFS('All sensors Installed'!$B:$B,$A34,'All sensors Installed'!$F:$F,G$1) -> 0 | H34: =COUNTIFS('All sensors Installed'!$B:$B,$A34,'All sensors Installed'!$F:$F,H$1) -> 12 | I34: =COUNTIFS('All sensors Installed'!$B:$B,$A34,'All sensors Installed'!$F:$F,I$1) -> 24 | ... P34: =COUNTIFS('All sensors Installed'!$B:$B,$A34,'All sensors Installed'!$F:$F,P$1) -> 0
